[2017-03-02 12:49:28,064] {models.py:154} INFO - Filling up the DagBag from /home/lavanya181194/airflow/dags/HellowWorld.py
[2017-03-02 12:49:28,645] {models.py:154} INFO - Filling up the DagBag from /home/lavanya181194/airflow/dags/HellowWorld.py
[2017-03-02 12:49:28,735] {models.py:1196} INFO - 
--------------------------------------------------------------------------------
Starting attempt 1 of 2
--------------------------------------------------------------------------------

[2017-03-02 12:49:28,744] {models.py:1219} INFO - Executing <Task(BashOperator): task_4> on 2017-02-28 06:25:00
[2017-03-02 12:49:28,753] {bash_operator.py:55} INFO - tmp dir root location: 
/tmp
[2017-03-02 12:49:28,754] {bash_operator.py:64} INFO - Temporary script location :/tmp/airflowtmp2NMGV_//tmp/airflowtmp2NMGV_/task_4zNMX4c
[2017-03-02 12:49:28,755] {bash_operator.py:65} INFO - Running command: bash try.sh 
[2017-03-02 12:49:28,758] {bash_operator.py:73} INFO - Output:
[2017-03-02 12:49:28,759] {bash_operator.py:77} INFO - bash: try.sh: No such file or directory
[2017-03-02 12:49:28,760] {bash_operator.py:80} INFO - Command exited with return code 127
[2017-03-02 12:49:28,760] {models.py:1286} ERROR - Bash command failed
Traceback (most recent call last):
  File "/home/lavanya181194/.local/lib/python2.7/site-packages/airflow/models.py", line 1245, in run
    result = task_copy.execute(context=context)
  File "/home/lavanya181194/.local/lib/python2.7/site-packages/airflow/operators/bash_operator.py", line 83, in execute
    raise AirflowException("Bash command failed")
AirflowException: Bash command failed
[2017-03-02 12:49:28,761] {models.py:1298} INFO - Marking task as UP_FOR_RETRY
[2017-03-02 12:49:28,771] {models.py:1327} ERROR - Bash command failed
[2017-03-02 12:50:31,413] {models.py:154} INFO - Filling up the DagBag from /home/lavanya181194/airflow/dags/HellowWorld.py
[2017-03-02 12:50:32,023] {models.py:154} INFO - Filling up the DagBag from /home/lavanya181194/airflow/dags/HellowWorld.py
[2017-03-02 12:50:32,116] {models.py:1196} INFO - 
--------------------------------------------------------------------------------
Starting attempt 2 of 2
--------------------------------------------------------------------------------

[2017-03-02 12:50:32,126] {models.py:1219} INFO - Executing <Task(BashOperator): task_4> on 2017-02-28 06:25:00
[2017-03-02 12:50:32,135] {bash_operator.py:55} INFO - tmp dir root location: 
/tmp
[2017-03-02 12:50:32,137] {bash_operator.py:64} INFO - Temporary script location :/tmp/airflowtmpagB8kW//tmp/airflowtmpagB8kW/task_4CqHM4K
[2017-03-02 12:50:32,137] {bash_operator.py:65} INFO - Running command: bash try.sh 
[2017-03-02 12:50:32,139] {bash_operator.py:73} INFO - Output:
[2017-03-02 12:50:32,141] {bash_operator.py:77} INFO - bash: try.sh: No such file or directory
[2017-03-02 12:50:32,141] {bash_operator.py:80} INFO - Command exited with return code 127
[2017-03-02 12:50:32,142] {models.py:1286} ERROR - Bash command failed
Traceback (most recent call last):
  File "/home/lavanya181194/.local/lib/python2.7/site-packages/airflow/models.py", line 1245, in run
    result = task_copy.execute(context=context)
  File "/home/lavanya181194/.local/lib/python2.7/site-packages/airflow/operators/bash_operator.py", line 83, in execute
    raise AirflowException("Bash command failed")
AirflowException: Bash command failed
[2017-03-02 12:50:32,143] {models.py:1304} INFO - All retries failed; marking task as FAILED
[2017-03-02 12:50:32,153] {models.py:1327} ERROR - Bash command failed
