[2017-03-02 12:48:39,445] {models.py:154} INFO - Filling up the DagBag from /home/lavanya181194/airflow/dags/HellowWorld.py
[2017-03-02 12:48:40,019] {models.py:154} INFO - Filling up the DagBag from /home/lavanya181194/airflow/dags/HellowWorld.py
[2017-03-02 12:48:40,109] {models.py:1196} INFO - 
--------------------------------------------------------------------------------
Starting attempt 1 of 2
--------------------------------------------------------------------------------

[2017-03-02 12:48:40,120] {models.py:1219} INFO - Executing <Task(BashOperator): task_4> on 2017-02-26 06:25:00
[2017-03-02 12:48:40,129] {bash_operator.py:55} INFO - tmp dir root location: 
/tmp
[2017-03-02 12:48:40,130] {bash_operator.py:64} INFO - Temporary script location :/tmp/airflowtmplkCPnE//tmp/airflowtmplkCPnE/task_4X6zu9q
[2017-03-02 12:48:40,130] {bash_operator.py:65} INFO - Running command: bash try.sh 
[2017-03-02 12:48:40,133] {bash_operator.py:73} INFO - Output:
[2017-03-02 12:48:40,135] {bash_operator.py:77} INFO - bash: try.sh: No such file or directory
[2017-03-02 12:48:40,135] {bash_operator.py:80} INFO - Command exited with return code 127
[2017-03-02 12:48:40,136] {models.py:1286} ERROR - Bash command failed
Traceback (most recent call last):
  File "/home/lavanya181194/.local/lib/python2.7/site-packages/airflow/models.py", line 1245, in run
    result = task_copy.execute(context=context)
  File "/home/lavanya181194/.local/lib/python2.7/site-packages/airflow/operators/bash_operator.py", line 83, in execute
    raise AirflowException("Bash command failed")
AirflowException: Bash command failed
[2017-03-02 12:48:40,137] {models.py:1298} INFO - Marking task as UP_FOR_RETRY
[2017-03-02 12:48:40,146] {models.py:1327} ERROR - Bash command failed
[2017-03-02 12:49:44,725] {models.py:154} INFO - Filling up the DagBag from /home/lavanya181194/airflow/dags/HellowWorld.py
[2017-03-02 12:49:45,324] {models.py:154} INFO - Filling up the DagBag from /home/lavanya181194/airflow/dags/HellowWorld.py
[2017-03-02 12:49:45,423] {models.py:1196} INFO - 
--------------------------------------------------------------------------------
Starting attempt 2 of 2
--------------------------------------------------------------------------------

[2017-03-02 12:49:45,434] {models.py:1219} INFO - Executing <Task(BashOperator): task_4> on 2017-02-26 06:25:00
[2017-03-02 12:49:45,444] {bash_operator.py:55} INFO - tmp dir root location: 
/tmp
[2017-03-02 12:49:45,445] {bash_operator.py:64} INFO - Temporary script location :/tmp/airflowtmpnSpKNf//tmp/airflowtmpnSpKNf/task_4CkTtad
[2017-03-02 12:49:45,445] {bash_operator.py:65} INFO - Running command: bash try.sh 
[2017-03-02 12:49:45,448] {bash_operator.py:73} INFO - Output:
[2017-03-02 12:49:45,450] {bash_operator.py:77} INFO - bash: try.sh: No such file or directory
[2017-03-02 12:49:45,450] {bash_operator.py:80} INFO - Command exited with return code 127
[2017-03-02 12:49:45,451] {models.py:1286} ERROR - Bash command failed
Traceback (most recent call last):
  File "/home/lavanya181194/.local/lib/python2.7/site-packages/airflow/models.py", line 1245, in run
    result = task_copy.execute(context=context)
  File "/home/lavanya181194/.local/lib/python2.7/site-packages/airflow/operators/bash_operator.py", line 83, in execute
    raise AirflowException("Bash command failed")
AirflowException: Bash command failed
[2017-03-02 12:49:45,452] {models.py:1304} INFO - All retries failed; marking task as FAILED
[2017-03-02 12:49:45,463] {models.py:1327} ERROR - Bash command failed
