[2017-03-02 07:40:30,585] {models.py:154} INFO - Filling up the DagBag from /home/lavanya181194/airflow/dags/example_dags/example_twitter_dag.py
[2017-03-02 07:40:31,155] {models.py:154} INFO - Filling up the DagBag from /home/lavanya181194/airflow/dags/example_dags/example_twitter_dag.py
[2017-03-02 07:40:31,247] {models.py:1196} INFO - 
--------------------------------------------------------------------------------
Starting attempt 1 of 2
--------------------------------------------------------------------------------

[2017-03-02 07:40:31,256] {models.py:1219} INFO - Executing <Task(BashOperator): put_fromTwitter_B_to_hdfs> on 2016-03-15 00:00:00
[2017-03-02 07:40:31,266] {bash_operator.py:55} INFO - tmp dir root location: 
/tmp
[2017-03-02 07:40:31,267] {bash_operator.py:64} INFO - Temporary script location :/tmp/airflowtmpf9KXp3//tmp/airflowtmpf9KXp3/put_fromTwitter_B_to_hdfssOsZFF
[2017-03-02 07:40:31,267] {bash_operator.py:65} INFO - Running command: HADOOP_USER_NAME=hdfs hadoop fs -put -f /tmp/from_fromTwitter_B_2017-03-01.csv /tmp/fromTwitter_B/
[2017-03-02 07:40:31,269] {bash_operator.py:73} INFO - Output:
[2017-03-02 07:40:31,271] {bash_operator.py:77} INFO - /tmp/airflowtmpf9KXp3/put_fromTwitter_B_to_hdfssOsZFF: line 1: hadoop: command not found
[2017-03-02 07:40:31,271] {bash_operator.py:80} INFO - Command exited with return code 127
[2017-03-02 07:40:31,271] {models.py:1286} ERROR - Bash command failed
Traceback (most recent call last):
  File "/home/lavanya181194/.local/lib/python2.7/site-packages/airflow/models.py", line 1245, in run
    result = task_copy.execute(context=context)
  File "/home/lavanya181194/.local/lib/python2.7/site-packages/airflow/operators/bash_operator.py", line 83, in execute
    raise AirflowException("Bash command failed")
AirflowException: Bash command failed
[2017-03-02 07:40:31,273] {models.py:1298} INFO - Marking task as UP_FOR_RETRY
[2017-03-02 07:40:31,283] {models.py:1327} ERROR - Bash command failed
