[2017-03-02 07:38:29,496] {models.py:154} INFO - Filling up the DagBag from /home/lavanya181194/airflow/dags/example_dags/example_twitter_dag.py
[2017-03-02 07:38:30,064] {models.py:154} INFO - Filling up the DagBag from /home/lavanya181194/airflow/dags/example_dags/example_twitter_dag.py
[2017-03-02 07:38:30,152] {models.py:1196} INFO - 
--------------------------------------------------------------------------------
Starting attempt 1 of 2
--------------------------------------------------------------------------------

[2017-03-02 07:38:30,161] {models.py:1219} INFO - Executing <Task(BashOperator): put_fromTwitter_C_to_hdfs> on 2016-03-13 00:00:00
[2017-03-02 07:38:30,170] {bash_operator.py:55} INFO - tmp dir root location: 
/tmp
[2017-03-02 07:38:30,171] {bash_operator.py:64} INFO - Temporary script location :/tmp/airflowtmpeCEOVP//tmp/airflowtmpeCEOVP/put_fromTwitter_C_to_hdfsGxpStY
[2017-03-02 07:38:30,171] {bash_operator.py:65} INFO - Running command: HADOOP_USER_NAME=hdfs hadoop fs -put -f /tmp/from_fromTwitter_C_2017-03-01.csv /tmp/fromTwitter_C/
[2017-03-02 07:38:30,174] {bash_operator.py:73} INFO - Output:
[2017-03-02 07:38:30,175] {bash_operator.py:77} INFO - /tmp/airflowtmpeCEOVP/put_fromTwitter_C_to_hdfsGxpStY: line 1: hadoop: command not found
[2017-03-02 07:38:30,175] {bash_operator.py:80} INFO - Command exited with return code 127
[2017-03-02 07:38:30,175] {models.py:1286} ERROR - Bash command failed
Traceback (most recent call last):
  File "/home/lavanya181194/.local/lib/python2.7/site-packages/airflow/models.py", line 1245, in run
    result = task_copy.execute(context=context)
  File "/home/lavanya181194/.local/lib/python2.7/site-packages/airflow/operators/bash_operator.py", line 83, in execute
    raise AirflowException("Bash command failed")
AirflowException: Bash command failed
[2017-03-02 07:38:30,177] {models.py:1298} INFO - Marking task as UP_FOR_RETRY
[2017-03-02 07:38:30,186] {models.py:1327} ERROR - Bash command failed
[2017-03-02 11:52:22,619] {models.py:154} INFO - Filling up the DagBag from /home/lavanya181194/airflow/dags/example_dags/example_twitter_dag.py
[2017-03-02 11:52:23,216] {models.py:154} INFO - Filling up the DagBag from /home/lavanya181194/airflow/dags/example_dags/example_twitter_dag.py
[2017-03-02 11:52:23,338] {models.py:1196} INFO - 
--------------------------------------------------------------------------------
Starting attempt 2 of 2
--------------------------------------------------------------------------------

[2017-03-02 11:52:23,349] {models.py:1219} INFO - Executing <Task(BashOperator): put_fromTwitter_C_to_hdfs> on 2016-03-13 00:00:00
[2017-03-02 11:52:23,359] {bash_operator.py:55} INFO - tmp dir root location: 
/tmp
[2017-03-02 11:52:23,360] {bash_operator.py:64} INFO - Temporary script location :/tmp/airflowtmp1fSqsA//tmp/airflowtmp1fSqsA/put_fromTwitter_C_to_hdfs8V2GFV
[2017-03-02 11:52:23,360] {bash_operator.py:65} INFO - Running command: HADOOP_USER_NAME=hdfs hadoop fs -put -f /tmp/from_fromTwitter_C_2017-03-01.csv /tmp/fromTwitter_C/
[2017-03-02 11:52:23,363] {bash_operator.py:73} INFO - Output:
[2017-03-02 11:52:23,364] {bash_operator.py:77} INFO - /tmp/airflowtmp1fSqsA/put_fromTwitter_C_to_hdfs8V2GFV: line 1: hadoop: command not found
[2017-03-02 11:52:23,365] {bash_operator.py:80} INFO - Command exited with return code 127
[2017-03-02 11:52:23,365] {models.py:1286} ERROR - Bash command failed
Traceback (most recent call last):
  File "/home/lavanya181194/.local/lib/python2.7/site-packages/airflow/models.py", line 1245, in run
    result = task_copy.execute(context=context)
  File "/home/lavanya181194/.local/lib/python2.7/site-packages/airflow/operators/bash_operator.py", line 83, in execute
    raise AirflowException("Bash command failed")
AirflowException: Bash command failed
[2017-03-02 11:52:23,367] {models.py:1304} INFO - All retries failed; marking task as FAILED
[2017-03-02 11:52:23,377] {models.py:1327} ERROR - Bash command failed
