[2017-03-02 12:25:44,173] {models.py:154} INFO - Filling up the DagBag from /home/lavanya181194/airflow/dags/HellowWorld.py
[2017-03-02 12:25:44,903] {models.py:154} INFO - Filling up the DagBag from /home/lavanya181194/airflow/dags/HellowWorld.py
[2017-03-02 12:25:45,005] {models.py:1196} INFO - 
--------------------------------------------------------------------------------
Starting attempt 1 of 2
--------------------------------------------------------------------------------

[2017-03-02 12:25:45,017] {models.py:1219} INFO - Executing <Task(BashOperator): task_4> on 2017-02-27 07:27:03.323749
[2017-03-02 12:25:45,027] {bash_operator.py:55} INFO - tmp dir root location: 
/tmp
[2017-03-02 12:25:45,028] {bash_operator.py:64} INFO - Temporary script location :/tmp/airflowtmpHkydjN//tmp/airflowtmpHkydjN/task_42A62PY
[2017-03-02 12:25:45,028] {bash_operator.py:65} INFO - Running command: bash try.sh 
[2017-03-02 12:25:45,031] {bash_operator.py:73} INFO - Output:
[2017-03-02 12:25:45,032] {bash_operator.py:77} INFO - bash: try.sh: No such file or directory
[2017-03-02 12:25:45,033] {bash_operator.py:80} INFO - Command exited with return code 127
[2017-03-02 12:25:45,033] {models.py:1286} ERROR - Bash command failed
Traceback (most recent call last):
  File "/home/lavanya181194/.local/lib/python2.7/site-packages/airflow/models.py", line 1245, in run
    result = task_copy.execute(context=context)
  File "/home/lavanya181194/.local/lib/python2.7/site-packages/airflow/operators/bash_operator.py", line 83, in execute
    raise AirflowException("Bash command failed")
AirflowException: Bash command failed
[2017-03-02 12:25:45,034] {models.py:1298} INFO - Marking task as UP_FOR_RETRY
[2017-03-02 12:25:45,044] {models.py:1327} ERROR - Bash command failed
