[2017-03-02 12:25:15,335] {models.py:154} INFO - Filling up the DagBag from /home/lavanya181194/airflow/dags/HellowWorld.py
[2017-03-02 12:25:15,938] {models.py:154} INFO - Filling up the DagBag from /home/lavanya181194/airflow/dags/HellowWorld.py
[2017-03-02 12:25:16,029] {models.py:1196} INFO - 
--------------------------------------------------------------------------------
Starting attempt 1 of 2
--------------------------------------------------------------------------------

[2017-03-02 12:25:16,039] {models.py:1219} INFO - Executing <Task(BashOperator): task_4> on 2017-02-26 07:27:03.323749
[2017-03-02 12:25:16,049] {bash_operator.py:55} INFO - tmp dir root location: 
/tmp
[2017-03-02 12:25:16,050] {bash_operator.py:64} INFO - Temporary script location :/tmp/airflowtmp5XQUet//tmp/airflowtmp5XQUet/task_4j3MXmb
[2017-03-02 12:25:16,050] {bash_operator.py:65} INFO - Running command: bash try.sh 
[2017-03-02 12:25:16,052] {bash_operator.py:73} INFO - Output:
[2017-03-02 12:25:16,054] {bash_operator.py:77} INFO - bash: try.sh: No such file or directory
[2017-03-02 12:25:16,054] {bash_operator.py:80} INFO - Command exited with return code 127
[2017-03-02 12:25:16,054] {models.py:1286} ERROR - Bash command failed
Traceback (most recent call last):
  File "/home/lavanya181194/.local/lib/python2.7/site-packages/airflow/models.py", line 1245, in run
    result = task_copy.execute(context=context)
  File "/home/lavanya181194/.local/lib/python2.7/site-packages/airflow/operators/bash_operator.py", line 83, in execute
    raise AirflowException("Bash command failed")
AirflowException: Bash command failed
[2017-03-02 12:25:16,055] {models.py:1298} INFO - Marking task as UP_FOR_RETRY
[2017-03-02 12:25:16,064] {models.py:1327} ERROR - Bash command failed
