[2017-03-02 07:40:24,944] {models.py:154} INFO - Filling up the DagBag from /home/lavanya181194/airflow/dags/example_dags/example_twitter_dag.py
[2017-03-02 07:40:25,506] {models.py:154} INFO - Filling up the DagBag from /home/lavanya181194/airflow/dags/example_dags/example_twitter_dag.py
[2017-03-02 07:40:25,595] {models.py:1196} INFO - 
--------------------------------------------------------------------------------
Starting attempt 1 of 2
--------------------------------------------------------------------------------

[2017-03-02 07:40:25,605] {models.py:1219} INFO - Executing <Task(BashOperator): put_fromTwitter_A_to_hdfs> on 2016-03-15 00:00:00
[2017-03-02 07:40:25,613] {bash_operator.py:55} INFO - tmp dir root location: 
/tmp
[2017-03-02 07:40:25,614] {bash_operator.py:64} INFO - Temporary script location :/tmp/airflowtmpHlQiBT//tmp/airflowtmpHlQiBT/put_fromTwitter_A_to_hdfsjhu63J
[2017-03-02 07:40:25,614] {bash_operator.py:65} INFO - Running command: HADOOP_USER_NAME=hdfs hadoop fs -put -f /tmp/from_fromTwitter_A_2017-03-01.csv /tmp/fromTwitter_A/
[2017-03-02 07:40:25,617] {bash_operator.py:73} INFO - Output:
[2017-03-02 07:40:25,618] {bash_operator.py:77} INFO - /tmp/airflowtmpHlQiBT/put_fromTwitter_A_to_hdfsjhu63J: line 1: hadoop: command not found
[2017-03-02 07:40:25,619] {bash_operator.py:80} INFO - Command exited with return code 127
[2017-03-02 07:40:25,619] {models.py:1286} ERROR - Bash command failed
Traceback (most recent call last):
  File "/home/lavanya181194/.local/lib/python2.7/site-packages/airflow/models.py", line 1245, in run
    result = task_copy.execute(context=context)
  File "/home/lavanya181194/.local/lib/python2.7/site-packages/airflow/operators/bash_operator.py", line 83, in execute
    raise AirflowException("Bash command failed")
AirflowException: Bash command failed
[2017-03-02 07:40:25,620] {models.py:1298} INFO - Marking task as UP_FOR_RETRY
[2017-03-02 07:40:25,629] {models.py:1327} ERROR - Bash command failed
[2017-03-02 11:39:02,052] {models.py:154} INFO - Filling up the DagBag from /home/lavanya181194/airflow/dags/example_dags/example_twitter_dag.py
[2017-03-02 11:39:02,622] {models.py:154} INFO - Filling up the DagBag from /home/lavanya181194/airflow/dags/example_dags/example_twitter_dag.py
[2017-03-02 11:39:02,712] {models.py:1196} INFO - 
--------------------------------------------------------------------------------
Starting attempt 2 of 2
--------------------------------------------------------------------------------

[2017-03-02 11:39:02,722] {models.py:1219} INFO - Executing <Task(BashOperator): put_fromTwitter_A_to_hdfs> on 2016-03-15 00:00:00
[2017-03-02 11:39:02,731] {bash_operator.py:55} INFO - tmp dir root location: 
/tmp
[2017-03-02 11:39:02,732] {bash_operator.py:64} INFO - Temporary script location :/tmp/airflowtmpCTEVyr//tmp/airflowtmpCTEVyr/put_fromTwitter_A_to_hdfs1llmh1
[2017-03-02 11:39:02,732] {bash_operator.py:65} INFO - Running command: HADOOP_USER_NAME=hdfs hadoop fs -put -f /tmp/from_fromTwitter_A_2017-03-01.csv /tmp/fromTwitter_A/
[2017-03-02 11:39:02,735] {bash_operator.py:73} INFO - Output:
[2017-03-02 11:39:02,736] {bash_operator.py:77} INFO - /tmp/airflowtmpCTEVyr/put_fromTwitter_A_to_hdfs1llmh1: line 1: hadoop: command not found
[2017-03-02 11:39:02,736] {bash_operator.py:80} INFO - Command exited with return code 127
[2017-03-02 11:39:02,736] {models.py:1286} ERROR - Bash command failed
Traceback (most recent call last):
  File "/home/lavanya181194/.local/lib/python2.7/site-packages/airflow/models.py", line 1245, in run
    result = task_copy.execute(context=context)
  File "/home/lavanya181194/.local/lib/python2.7/site-packages/airflow/operators/bash_operator.py", line 83, in execute
    raise AirflowException("Bash command failed")
AirflowException: Bash command failed
[2017-03-02 11:39:02,738] {models.py:1304} INFO - All retries failed; marking task as FAILED
[2017-03-02 11:39:02,747] {models.py:1327} ERROR - Bash command failed
