[2017-03-02 07:38:52,044] {models.py:154} INFO - Filling up the DagBag from /home/lavanya181194/airflow/dags/example_dags/example_twitter_dag.py
[2017-03-02 07:38:52,617] {models.py:154} INFO - Filling up the DagBag from /home/lavanya181194/airflow/dags/example_dags/example_twitter_dag.py
[2017-03-02 07:38:52,708] {models.py:1196} INFO - 
--------------------------------------------------------------------------------
Starting attempt 1 of 2
--------------------------------------------------------------------------------

[2017-03-02 07:38:52,718] {models.py:1219} INFO - Executing <Task(BashOperator): put_fromTwitter_D_to_hdfs> on 2016-03-13 00:00:00
[2017-03-02 07:38:52,727] {bash_operator.py:55} INFO - tmp dir root location: 
/tmp
[2017-03-02 07:38:52,729] {bash_operator.py:64} INFO - Temporary script location :/tmp/airflowtmpKq186S//tmp/airflowtmpKq186S/put_fromTwitter_D_to_hdfsXwPANP
[2017-03-02 07:38:52,729] {bash_operator.py:65} INFO - Running command: HADOOP_USER_NAME=hdfs hadoop fs -put -f /tmp/from_fromTwitter_D_2017-03-01.csv /tmp/fromTwitter_D/
[2017-03-02 07:38:52,731] {bash_operator.py:73} INFO - Output:
[2017-03-02 07:38:52,733] {bash_operator.py:77} INFO - /tmp/airflowtmpKq186S/put_fromTwitter_D_to_hdfsXwPANP: line 1: hadoop: command not found
[2017-03-02 07:38:52,733] {bash_operator.py:80} INFO - Command exited with return code 127
[2017-03-02 07:38:52,733] {models.py:1286} ERROR - Bash command failed
Traceback (most recent call last):
  File "/home/lavanya181194/.local/lib/python2.7/site-packages/airflow/models.py", line 1245, in run
    result = task_copy.execute(context=context)
  File "/home/lavanya181194/.local/lib/python2.7/site-packages/airflow/operators/bash_operator.py", line 83, in execute
    raise AirflowException("Bash command failed")
AirflowException: Bash command failed
[2017-03-02 07:38:52,735] {models.py:1298} INFO - Marking task as UP_FOR_RETRY
[2017-03-02 07:38:52,743] {models.py:1327} ERROR - Bash command failed
