[2017-03-02 11:52:16,947] {models.py:154} INFO - Filling up the DagBag from /home/lavanya181194/airflow/dags/example_dags/example_twitter_dag.py
[2017-03-02 11:52:17,530] {models.py:154} INFO - Filling up the DagBag from /home/lavanya181194/airflow/dags/example_dags/example_twitter_dag.py
[2017-03-02 11:52:17,622] {models.py:1196} INFO - 
--------------------------------------------------------------------------------
Starting attempt 1 of 2
--------------------------------------------------------------------------------

[2017-03-02 11:52:17,632] {models.py:1219} INFO - Executing <Task(BashOperator): put_fromTwitter_D_to_hdfs> on 2016-03-15 00:00:00
[2017-03-02 11:52:17,641] {bash_operator.py:55} INFO - tmp dir root location: 
/tmp
[2017-03-02 11:52:17,642] {bash_operator.py:64} INFO - Temporary script location :/tmp/airflowtmpowSrYF//tmp/airflowtmpowSrYF/put_fromTwitter_D_to_hdfsIb6QxB
[2017-03-02 11:52:17,642] {bash_operator.py:65} INFO - Running command: HADOOP_USER_NAME=hdfs hadoop fs -put -f /tmp/from_fromTwitter_D_2017-03-01.csv /tmp/fromTwitter_D/
[2017-03-02 11:52:17,644] {bash_operator.py:73} INFO - Output:
[2017-03-02 11:52:17,646] {bash_operator.py:77} INFO - /tmp/airflowtmpowSrYF/put_fromTwitter_D_to_hdfsIb6QxB: line 1: hadoop: command not found
[2017-03-02 11:52:17,646] {bash_operator.py:80} INFO - Command exited with return code 127
[2017-03-02 11:52:17,646] {models.py:1286} ERROR - Bash command failed
Traceback (most recent call last):
  File "/home/lavanya181194/.local/lib/python2.7/site-packages/airflow/models.py", line 1245, in run
    result = task_copy.execute(context=context)
  File "/home/lavanya181194/.local/lib/python2.7/site-packages/airflow/operators/bash_operator.py", line 83, in execute
    raise AirflowException("Bash command failed")
AirflowException: Bash command failed
[2017-03-02 11:52:17,648] {models.py:1298} INFO - Marking task as UP_FOR_RETRY
[2017-03-02 11:52:17,657] {models.py:1327} ERROR - Bash command failed
